Workbook

Sheet Hướng dẫn
A1: Agricovi – Mô hình doanh thu (bản để nhà đầu tư tự đổi giả định)
A3: Cách dùng
A4: 1. Mở trang 'Giả định'. Chỉ sửa các ô màu vàng.
A5: 2. Trang 'Dự phóng' tự tính lại doanh thu 3 năm, chi phí và lợi nhuận.
A6: 3. Giá thuê bao (4 gói) lấy theo quyết định D4 của chủ sản phẩm. Các nguồn thu còn lại chưa chốt giá nên để 0, hãy điền thử.
A8: Lưu ý
A9: - Số lượng khách các năm là GIẢ ĐỊNH để thảo luận, không phải số liệu thực tế hay cam kết.
A10: - Doanh thu thuê bao tính theo 'quy năm': số khách cuối năm nhân giá cả năm (run-rate), chưa chia theo tháng bắt đầu.
A11: - Chưa tính thuế, chiết khấu, khách dùng thử miễn phí 1 tháng, khách rời bỏ giữa năm.
A12: - Chi phí ở mục 5 là ƯỚC TÍNH của người soạn (lương, chi phí thu hút khách, hạ tầng...), chạy theo số khách. Hãy thay bằng báo giá thực tế.

Sheet Giả định
A1: GIẢ ĐỊNH (chỉ sửa ô màu vàng)
A3: 1. Giá thuê bao (đồng mỗi quý) – theo quyết định D4
A4: Gói | B4: Giá/quý | C4: Số vụ | E4: Ghi chú
A5: Hộ cơ bản | B5: 1200000 | C5: 3 | E5: Dùng thử 1 tháng, sau đó thu theo quý
A6: Hộ nâng cao | B6: 1800000 | C6: 6
A7: HTX cơ bản | B7: 2400000 | C7: 8
A8: HTX nâng cao | B8: 4500000 | C8: 15
A10: 2. Cơ cấu gói
A11: Tỷ lệ hộ chọn gói nâng cao | B11: 0.5
A12: Tỷ lệ HTX chọn gói nâng cao | B12: 0.5
A14: 3. Số khách trả phí cuối năm (giả định)
A15: Chỉ tiêu | B15: Năm 1 | C15: Năm 2 | D15: Năm 3 | E15: Ghi chú
A16: Hộ trả phí | B16: 200 | C16: 600 | D16: 1500 | E16: Thay bằng số liệu thí điểm khi có
A17: HTX trả phí | B17: 50 | C17: 100 | D17: 300
A19: 4. Nguồn thu từ website (chưa chốt giá, điền thử)
A20: Chỉ tiêu | B20: Năm 1 | C20: Năm 2 | D20: Năm 3 | E20: Ghi chú
A21: Số cơ sở mua gói ưu tiên hiển thị | B21: 0 | C21: 0 | D21: 0
A22: Phí ưu tiên hiển thị (đồng/cơ sở/năm) | B22: 0 | C22: 0 | D22: 0
A23: Số nhà cung cấp mở gian hàng vật tư | B23: 0 | C23: 0 | D23: 0
A24: Phí gian hàng (đồng/gian hàng/năm) | B24: 0 | C24: 0 | D24: 0
A25: Doanh thu quảng cáo, tin tài trợ (đồng/năm) | B25: 0 | C25: 0 | D25: 0 | E25: Nhập tổng số
A26: Giá trị đơn hàng giao thương qua website (đồng/năm) | B26: 0 | C26: 0 | D26: 0 | E26: Chỉ khi đã có tư vấn pháp lý
A27: Tỷ lệ hoa hồng trên đơn | B27: 0 | C27: 0 | D27: 0
A28: Doanh thu dữ liệu và dịch vụ liên kết (đồng/năm) | B28: 0 | C28: 0 | D28: 0 | E28: Dài hạn
A30: 5. Chi phí – tham số (ước tính của người soạn, hãy chỉnh theo thực tế)
A31: Khoản | B31: Năm 1 | C31: Năm 2 | D31: Năm 3 | E31: Ghi chú
A32: Số kỹ sư, kỹ thuật | B32: 2 | C32: 3 | D32: 5 | E32: Phát triển, vận hành hệ thống, bảo mật
A33: Số nhân viên bán hàng, phát triển thị trường | B33: 2 | C33: 4 | D33: 10 | E33: Bán qua HTX, đại lý, đi vùng trồng
A34: Số khách trên mỗi nhân viên hỗ trợ | B34: 600 | C34: 600 | D34: 600 | E34: Hỗ trợ, đào tạo, trả lời
A35: Số quản lý, vận hành, biên tập nội dung | B35: 1 | C35: 2 | D35: 3 | E35: Gồm người nhập tin và giá cho website
A36: Lương kỹ sư (đồng/tháng) | B36: 10000000 | C36: 15000000 | D36: 30000000 | E36: Chưa gồm hệ số chi phí ngoài lương
A37: Lương bán hàng (đồng/tháng) | B37: 12000000 | C37: 12000000 | D37: 12000000 | E37: Chưa gồm hoa hồng (nằm trong chi phí thu hút khách)
A38: Lương hỗ trợ khách (đồng/tháng) | B38: 0 | C38: 8000000 | D38: 10000000
A39: Lương quản lý, biên tập (đồng/tháng) | B39: 15000000 | C39: 15000000 | D39: 15000000
A40: Hệ số chi phí ngoài lương | B40: 1.2 | C40: 1.2 | D40: 1.2 | E40: Bảo hiểm, thiết bị, phần mềm làm việc
A41: Chi phí thu hút mỗi hộ mới (đồng) | B41: 500000 | C41: 500000 | D41: 500000 | E41: Quảng cáo, hoa hồng giới thiệu, đào tạo ban đầu
A42: Chi phí thu hút mỗi HTX mới (đồng) | B42: 1000000 | C42: 1000000 | D42: 1000000 | E42: Cần đi gặp, hướng dẫn tại chỗ
A43: Marketing thương hiệu cố định (đồng/năm) | B43: 100000000 | C43: 200000000 | D43: 300000000 | E43: Nội dung, sự kiện, hội chợ, truyền thông
A44: Hạ tầng cố định (đồng/năm) | B44: 60000000 | C44: 150000000 | D44: 400000000 | E44: Máy chủ, cơ sở dữ liệu, email, tên miền, giám sát
A45: Hạ tầng biến đổi mỗi hộ (đồng/năm) | B45: 80000 | C45: 80000 | D45: 80000 | E45: Lưu trữ, ảnh chấm công, thông báo
...

Sheet Dự phóng
A1: DỰ PHÓNG DOANH THU 3 NĂM (đồng, tự tính)
A3: Chỉ tiêu | B3: Năm 1 | C3: Năm 2 | D3: Năm 3
A4: Giá bình quân hộ (đồng/năm) | B4: =('Giả định'!$B$5*(1-'Giả định'!$B$11)+'Giả định'!$B$6*'Giả định'!$B$11)*4 -> 6000000 | C4: =('Giả định'!$B$5*(1-'Giả định'!$B$11)+'Giả định'!$B$6*'Giả định'!$B$11)*4 -> 6000000 | D4: =('Giả định'!$B$5*(1-'Giả định'!$B$11)+'Giả định'!$B$6*'Giả định'!$B$11)*4 -> 6000000
A5: Giá bình quân HTX (đồng/năm) | B5: =('Giả định'!$B$7*(1-'Giả định'!$B$12)+'Giả định'!$B$8*'Giả định'!$B$12)*4 -> 13800000 | C5: =('Giả định'!$B$7*(1-'Giả định'!$B$12)+'Giả định'!$B$8*'Giả định'!$B$12)*4 -> 13800000 | D5: =('Giả định'!$B$7*(1-'Giả định'!$B$12)+'Giả định'!$B$8*'Giả định'!$B$12)*4 -> 13800000
A6: Thuê bao hộ | B6: ='Giả định'!B16*B4 -> 1200000000 | C6: ='Giả định'!C16*C4 -> 3600000000 | D6: ='Giả định'!D16*D4 -> 9000000000
A7: Thuê bao HTX | B7: ='Giả định'!B17*B5 -> 690000000 | C7: ='Giả định'!C17*C5 -> 1380000000 | D7: ='Giả định'!D17*D5 -> 4140000000
A8: Tổng thuê bao app | B8: =B6+B7 -> 1890000000 | C8: =C6+C7 -> 4980000000 | D8: =D6+D7 -> 13140000000
A9: Ưu tiên hiển thị | B9: ='Giả định'!B21*'Giả định'!B22 -> 0 | C9: ='Giả định'!C21*'Giả định'!C22 -> 0 | D9: ='Giả định'!D21*'Giả định'!D22 -> 0
A10: Gian hàng vật tư | B10: ='Giả định'!B23*'Giả định'!B24 -> 0 | C10: ='Giả định'!C23*'Giả định'!C24 -> 0 | D10: ='Giả định'!D23*'Giả định'!D24 -> 0
A11: Quảng cáo, tin tài trợ | B11: ='Giả định'!B25 -> 0 | C11: ='Giả định'!C25 -> 0 | D11: ='Giả định'!D25 -> 0
A12: Hoa hồng giao thương | B12: ='Giả định'!B26*'Giả định'!B27 -> 0 | C12: ='Giả định'!C26*'Giả định'!C27 -> 0 | D12: ='Giả định'!D26*'Giả định'!D27 -> 0
A13: Dữ liệu và dịch vụ liên kết | B13: ='Giả định'!B28 -> 0 | C13: ='Giả định'!C28 -> 0 | D13: ='Giả định'!D28 -> 0
A14: Tổng nguồn thu website và khác | B14: =SUM(B9:B13) -> 0 | C14: =SUM(C9:C13) -> 0 | D14: =SUM(D9:D13) -> 0
A15: TỔNG DOANH THU | B15: =B8+B14 -> 1890000000 | C15: =C8+C14 -> 4980000000 | D15: =D8+D14 -> 13140000000
A16: Hộ mới trong năm | B16: ='Giả định'!B16 -> 200 | C16: 600 | D16: 1500
A17: HTX mới trong năm | B17: ='Giả định'!B17 -> 50 | C17: 100 | D17: 250
A18: Nhân sự | B18: =('Giả định'!B32*'Giả định'!B36+'Giả định'!B33*'Giả định'!B37+MAX(1,ROUNDUP(('Giả định'!B16+'Giả định'!B17)/'Giả định'!B34,0))*'Giả định'!B38+'Giả định'!B35*'Giả định'!B39)*12*'Giả định'!B40 -> 849600000 | C18: =('Giả định'!C32*'Giả định'!C36+'Giả định'!C33*'Giả định'!C37+MAX(1,ROUNDUP(('Giả định'!C16+'Giả định'!C17)/'Giả định'!C34,0))*'Giả định'!C38+'Giả định'!C35*'Giả định'!C39)*12*'Giả định'!C40 -> 2001600000 | D18: =('Giả định'!D32*'Giả định'!D36+'Giả định'!D33*'Giả định'!D37+MAX(1,ROUNDUP(('Giả định'!D16+'Giả định'!D17)/'Giả định'!D34,0))*'Giả định'!D38+'Giả định'!D35*'Giả định'!D39)*12*'Giả định'!D40 -> 4968000000
A19: Thu hút khách mới (marketing, bán hàng) | B19: =B16*'Giả định'!B41+B17*'Giả định'!B42 -> 150000000 | C19: =C16*'Giả định'!C41+C17*'Giả định'!C42 -> 400000000 | D19: =D16*'Giả định'!D41+D17*'Giả định'!D42 -> 1000000000
A20: Marketing thương hiệu | B20: ='Giả định'!B43 -> 100000000 | C20: ='Giả định'!C43 -> 200000000 | D20: ='Giả định'!D43 -> 300000000
A21: Hạ tầng | B21: ='Giả định'!B44+'Giả định'!B16*'Giả định'!B45+'Giả định'!B17*'Giả định'!B46 -> 86000000 | C21: ='Giả định'!C44+'Giả định'!C16*'Giả định'!C45+'Giả định'!C17*'Giả định'!C46 -> 228000000 | D21: ='Giả định'!D44+'Giả định'!D16*'Giả định'!D45+'Giả định'!D17*'Giả định'!D46 -> 610000000
A22: Phí cổng thanh toán | B22: =B8*'Giả định'!B47 -> 28350000 | C22: =C8*'Giả định'!C47 -> 74700000 | D22: =D8*'Giả định'!D47 -> 197100000
A23: Pháp lý, tuân thủ | B23: ='Giả định'!B48 -> 50000000 | C23: ='Giả định'!C48 -> 200000000 | D23: ='Giả định'!D48 -> 300000000
A24: Văn phòng, kế toán, hành chính | B24: ='Giả định'!B49 -> 50000000 | C24: ='Giả định'!C49 -> 240000000 | D24: ='Giả định'!D49 -> 480000000
A25: Dự phòng | B25: =SUM(B18:B24)*'Giả định'!B50 -> 131395000 | C25: =SUM(C18:C24)*'Giả định'!C50 -> 334430000 | D25: =SUM(D18:D24)*'Giả định'!D50 -> 785510000
A26: TỔNG CHI PHÍ | B26: =SUM(B18:B25) -> 1445345000 | C26: =SUM(C18:C25) -> 3678730000 | D26: =SUM(D18:D25) -> 8640610000
A27: LỢI NHUẬN (trước thuế) | B27: =B15-B26 -> 444655000 | C27: =C15-C26 -> 1301270000 | D27: =D15-D26 -> 4499390000
A28: Lợi nhuận lũy kế | B28: =B27 -> 444655000 | C28: =B28+C27 -> 1745925000 | D28: =C28+D27 -> 6245315000
A29: Vốn cần tối thiểu (mức lỗ lũy kế sâu nhất) | D29: =-MIN(0,MIN(B28:D28)) -> 0
A30: Thuê bao app chiếm trong tổng doanh thu | B30: =IF(B15=0,0,B8/B15) -> 1 | C30: =IF(C15=0,0,C8/C15) -> 1 | D30: =IF(D15=0,0,D8/D15) -> 1
A32: Lưu ý: số khách và mọi tham số chi phí là ước tính để thảo luận. 'Vốn cần tối thiểu' là mức lỗ lũy kế sâu nhất trong 3 năm, chưa gồm vốn lưu động, chưa tính thuế và khách dùng thử miễn phí.
